<?xml version="1.0" ?>
<robot xmlns:xacro="http://www.ros.org/wiki/xacro" name="firefighter">
    <xacro:property name="width" value=".2" />
    <link name="world" />
    
    <!-- Base Joint -->
    <joint name="base_joint" type="fixed">
        <parent link="world" />
        <child link="base" />
    </joint>
    <link name="base">
        <visual>
            <geometry>
                <!--- 0.0 0 -0.04  1.5708 3.14159-->
                <mesh filename="package://mycobot_description/urdf/mypalletizer_260_m5/base.dae" />
            </geometry>
            <!-- <origin xyz = " 0 -0.28 0.051 " rpy = " 1.5707963 0 1.5707963"/> -->
            <origin xyz=" 0 -0.28 0.051 " rpy=" 1.5707963 0 -1.5707963" />
        </visual>
        <collision>
            <geometry>
                <!--- 0.0 0 -0.04  1.5708 3.14159-->
                <mesh filename="package://mycobot_description/urdf/mypalletizer_260_m5/base.dae" />
            </geometry>
            <!-- <origin xyz = " 0 -0.28 0.051 " rpy = " 1.5707963 0 1.5707963"/> -->
            <origin xyz=" 0 -0.28 0.055 " rpy=" 1.5707963 0 -1.5707963" />
        </collision>
        <selfCollide>true</selfCollide>
        <inertial>
            <mass value="10000.0" />
            <inertia ixx="100" iyy="100" izz="100" ixy="0.0" ixz="0.0" iyz="0.0" />
        </inertial>
    </link>
    <link name="link1">
        <visual>
            <geometry>
                <mesh filename="package://mycobot_description/urdf/mypalletizer_260_m5/link1.dae" />
            </geometry>
            <origin xyz="0 -0.282  -0.115 " rpy=" 1.5707963 0 -1.5707963" />
        </visual>
        <collision>
            <geometry>
                <mesh filename="package://mycobot_description/urdf/mypalletizer_260_m5/link1.dae" />
            </geometry>
            <origin xyz="0 -0.282  -0.115 " rpy=" 1.5707963 0 -1.5707963" />
        </collision>
        <selfCollide>true</selfCollide>
        <inertial>
            <mass value="10.0" />
            <origin xyz="0 0 0" rpy="0 0 0" />
            <inertia ixx="1" iyy="1" izz="1" ixy="0.0" ixz="0.0" iyz="0.0" />
        </inertial>
    </link>
    <link name="link2">
        <visual>
            <geometry>
                <mesh filename="package://mycobot_description/urdf/mypalletizer_260_m5/link2.dae" />
            </geometry>
            <origin xyz="0  0.105 -0.414  " rpy=" 0 1.5707963 3.1415926" />
        </visual>
        <collision>
            <geometry>
                <mesh filename="package://mycobot_description/urdf/mypalletizer_260_m5/link2.dae" />
            </geometry>
            <origin xyz="0  0.105 -0.414  " rpy=" 0 1.5707963 3.1415926" />
        </collision>
        <selfCollide>true</selfCollide>
        <inertial>
            <mass value="10.0" />
            <origin xyz="0 0 0" rpy="0 0 0" />
            <inertia ixx="0.5" iyy="0.5" izz="0.5" ixy="0.0" ixz="0.0" iyz="0.0" />
        </inertial>
    </link>
    <link name="link3">
        <visual>
            <geometry>
                <!--- 0.0 0 -0.04 -->
                <mesh filename="package://mycobot_description/urdf/mypalletizer_260_m5/link3.dae" />
            </geometry>
            <origin xyz="0 0.235  -0.325 " rpy="0 1.5707963  3.1419626" />
        </visual>
        <collision>
            <geometry>
                <!--- 0.0 0 -0.04 -->
                <mesh filename="package://mycobot_description/urdf/mypalletizer_260_m5/link3.dae" />
            </geometry>
            <origin xyz="0 0.235  -0.325 " rpy="0 1.5707963  3.1419626" />
        </collision>
        <selfCollide>true</selfCollide>
        <inertial>
            <mass value="5.0" />
            <origin xyz="0 0 0" rpy="0 0 0" />
            <inertia ixx="0.5" iyy="0.5" izz="0.5" ixy="0.0" ixz="0.0" iyz="0.0" />
        </inertial>
    </link>
    <link name="link4">
        <visual>
            <geometry>
                <!--- 0.0 0 -0.04 -->
                <mesh filename="package://mycobot_description/urdf/mypalletizer_260_m5/link4.dae" />
            </geometry>
            <origin xyz="-0.12 -0.235  0.252" rpy=" 0 -1.5707963  0" />
        </visual>
        <collision>
            <geometry>
                <!--- 0.0 0 -0.04 -->
                <mesh filename="package://mycobot_description/urdf/mypalletizer_260_m5/link4.dae" />
            </geometry>
            <origin xyz="-0.12 -0.235  0.252" rpy=" 0 -1.5707963  0" />
        </collision>
        <inertial>
            <mass value="5.0" />
            <origin xyz="0 0 0" rpy="0 0 0" />
            <inertia ixx="0.2" iyy="0.2" izz="0.2" ixy="0.0" ixz="0.0" iyz="0.0" />
        </inertial>
    </link>
    <link name="link5">
        <visual>
            <geometry>
                <!--- 0.0 0 -0.04 -->
                <cylinder length="0.015" radius="0.0152" />
                <!-- <mesh filename="package://mycobot_description/urdf/mypalletizer_260_m5/link5.dae"/> -->
            </geometry>
            <material name="grey">
                <color rgba="0.5 0.5 0.5 1" />
            </material>
            <origin xyz="0 -0.001 0.01 " rpy=" 0 0 0" />
        </visual>
        <collision>
            <geometry>
                <!--- 0.0 0 -0.04 -->
                <cylinder length="0.015" radius="0.0152" />
            </geometry>
            <origin xyz="0 -0.001 0.01 " rpy=" 0 0 0" />
        </collision>
        <selfCollide>true</selfCollide>
        <inertial>
            <mass value="1.0" />
            <origin xyz="0 0 0" rpy="0 0 0" />
            <inertia ixx="0.2" iyy="0.2" izz="0.2" ixy="0.0" ixz="0.0" iyz="0.0" />
        </inertial>
    </link>
    <link name="gripper_base">
        <visual>
            <geometry>
                <mesh filename="package://mycobot_description/urdf/adaptive_gripper/gripper_base.dae" />
            </geometry>
            <origin xyz="0.0 0 -0.012 " rpy=" 0 0 0" />
        </visual>
        <collision>
            <geometry>
                <cylinder radius="0.02" length="0.01" />
            </geometry>
            <origin xyz="0.0 0 0.01 " rpy=" 0 0 0" />
        </collision>
        <inertial>
            <mass value="0.05" />
            <origin xyz="0 0 0" rpy="0 0 0" />
            <inertia ixx="0.03" iyy="0.03" izz="0.03" ixy="0.0" ixz="0.0" iyz="0.0" />
        </inertial>
    </link>
    <link name="gripper_left1">
        <visual>
            <geometry>
                <mesh filename="package://mycobot_description/urdf/adaptive_gripper/gripper_left1.dae" />
            </geometry>
            <origin xyz="0.039 -0.0133 -0.012 " rpy=" 0 0 0" />
        </visual>
        <collision>
            <geometry>
                <cylinder radius="0.0034" length="0.005" />
            </geometry>
            <origin xyz="0.0 0.0 -0.008 " rpy=" 0 0 0" />
        </collision>
        <inertial>
            <mass value="0.0005" />
            <origin xyz="0 0 0" rpy="0 0 0" />
            <inertia ixx="0.03" iyy="0.03" izz="0.03" ixy="0.0" ixz="0.0" iyz="0.0" />
        </inertial>
    </link>
    <link name="gripper_left2">
        <visual>
            <geometry>
                <mesh filename="package://mycobot_description/urdf/adaptive_gripper/gripper_left2.dae" />
            </geometry>
            <origin xyz="0.005 -0.0195 -0.012 " rpy=" 0 0 0" />
        </visual>
        <collision>
            <geometry>
                <cylinder radius="0.0034" length="0.005" />
            </geometry>
            <origin xyz="0.00 -0.0 -0.001 " rpy=" 0 0 0" />
        </collision>
        <inertial>
            <mass value="0.0005" />
            <origin xyz="0 0 0" rpy="0 0 0" />
            <inertia ixx="0.03" iyy="0.03" izz="0.03" ixy="0.0" ixz="0.0" iyz="0.0" />
        </inertial>
    </link>
    <link name="gripper_left3">
        <visual>
            <geometry>
                <mesh filename="package://mycobot_description/urdf/adaptive_gripper/gripper_left3.dae" />
            </geometry>
            <origin xyz="0.012 0.0025 -0.012 " rpy=" 0 0 0" />
        </visual>
        <collision>
            <geometry>
                <cylinder radius="0.0034" length="0.005" />
            </geometry>
            <origin xyz="0.0  0 0.0 " rpy=" 0 0 0" />
        </collision>
        <inertial>
            <mass value="0.0005" />
            <origin xyz="0 0 0" rpy="0 0 0" />
            <inertia ixx="0.03" iyy="0.03" izz="0.03" ixy="0.0" ixz="0.0" iyz="0.0" />
        </inertial>
    </link>
    <link name="gripper_right1">
        <visual>
            <geometry>
                <mesh filename="package://mycobot_description/urdf/adaptive_gripper/gripper_right1.dae" />
            </geometry>
            <origin xyz="-0.039 -0.0133 -0.012 " rpy=" 0 0 0" />
        </visual>
        <collision>
            <geometry>
                <cylinder radius="0.0034" length="0.005" />
            </geometry>
            <origin xyz="0.0 0.0 -0.008 " rpy=" 0 0 0" />
        </collision>
        <inertial>
            <mass value="0.0005" />
            <origin xyz="0 0 0" rpy="0 0 0" />
            <inertia ixx="0.03" iyy="0.03" izz="0.03" ixy="0.0" ixz="0.0" iyz="0.0" />
        </inertial>
    </link>
    <link name="gripper_right2">
        <visual>
            <geometry>
                <mesh filename="package://mycobot_description/urdf/adaptive_gripper/gripper_right2.dae" />
            </geometry>
            <origin xyz="-0.005 -0.0195 -0.012 " rpy=" 0 0 0" />
        </visual>
        <collision>
            <geometry>
                <cylinder radius="0.0034" length="0.005" />
            </geometry>
            <origin xyz="0.0 0.0 -0.001 " rpy=" 0 0 0" />
        </collision>
        <inertial>
            <mass value="0.0005" />
            <origin xyz="0 0 0" rpy="0 0 0" />
            <inertia ixx="0.03" iyy="0.03" izz="0.03" ixy="0.0" ixz="0.0" iyz="0.0" />
        </inertial>
    </link>
    <link name="gripper_right3">
        <visual>
            <geometry>
                <mesh filename="package://mycobot_description/urdf/adaptive_gripper/gripper_right3.dae" />
            </geometry>
            <origin xyz="-0.012 0.0025 -0.012 " rpy=" 0 0 0" />
        </visual>
        <collision>
            <geometry>
                <cylinder radius="0.0034" length="0.005" />
            </geometry>
            <origin xyz="0.0 0 0.0" rpy=" 0 0 0" />
        </collision>
        <inertial>
            <mass value="0.0005" />
            <origin xyz="0 0 0" rpy="0 0 0" />
            <inertia ixx="0.03" iyy="0.03" izz="0.03" ixy="0.0" ixz="0.0" iyz="0.0" />
        </inertial>
    </link>
    <joint name="joint1_to_base" type="revolute">
        <axis xyz="0 0 1" />
        <limit effort="1000.0" lower="-2.824" upper="2.824" velocity="1" />
        <parent link="base" />
        <child link="link1" />
        <origin xyz="0 0 0.12" rpy="0 0 0" />
        <dynamics damping="0.1" friction="0.1"/>
    </joint>
    <joint name="joint2_to_joint1" type="revolute">
        <axis xyz="0 0 1" />
        <limit effort="1000.0" lower="-0.0349" upper="1.5708" velocity="1" />
        <parent link="link1" />
        <child link="link2" />
        <origin xyz="0 0 0.0" rpy=" -1.5707963 0 0 " />
        <dynamics damping="0.1" friction="0.1"/>
    </joint>
    <joint name="joint3_to_joint2" type="revolute">
        <axis xyz=" 0 0 1" />
        <limit effort="1000.0" lower="-1.6057" upper="1.0471" velocity="1" />
        <parent link="link2" />
        <child link="link3" />
        <origin xyz="0.0 -0.14 0   " rpy="0 0 0 " />
        <dynamics damping="0.1" friction="0.1"/>
    </joint>
    <joint name="joint4_to_joint3" type="revolute">
        <axis xyz=" 0 0 1"/>
        <limit effort = "1000.0" lower = "0" upper = "1.5707963" velocity = "1"/> 
        <parent link="link3" />
        <child link="link4" />
        <origin xyz="0.134 -0.005   0.0" rpy="3.1415926 0 0 " />
        <dynamics damping="0.1" friction="0.1"/>
    </joint>
    <joint name="joint5_to_joint4" type="revolute">
        <axis xyz="0 0 1" />
        <limit effort="1000.0" lower="-3.14" upper="3.14" velocity="1" />
        <parent link="link4" />
        <child link="link5" />
        <origin xyz=" 0.044 0 0" rpy="  1.5707963 0 0 " />
        <dynamics damping="0.1" friction="0.1"/>
        <!-- <origin xyz= " 0.178 0 -0.005" rpy = "  -1.5707963 0 0 "/>   -->
    </joint>
    <joint name="joint5output_to_gripper_base" type="fixed">
        <parent link="link5" />
        <child link="gripper_base" />
        <!-- <origin xyz= "0 0.0 0" rpy = "-1.5708 0 0"/>   -->
        <origin xyz="0 0 0.051" rpy="1.579 0 1.5708" />
        <dynamics damping="0.1" friction="0.1"/>
    </joint>
    <joint name="gripper_controller" type="revolute">
        <axis xyz="0 0 1" />
        <limit effort="1000.0" lower="-0.599" upper="0.15" velocity="1" />
        <parent link="gripper_base" />
        <child link="gripper_left3" />
        <origin xyz="-0.012 0.005 0" rpy="0 0 0" />
        <dynamics damping="20.0" friction="0.1"/>
    </joint>
    <joint name="gripper_base_to_gripper_left2" type="revolute">
        <axis xyz="0 0 1" />
        <limit effort="1000.0" lower="-0.8" upper="0.5" velocity="1" />
        <parent link="gripper_base" />
        <child link="gripper_left2" />
        <origin xyz="-0.005 0.027 0" rpy="0 0 0" />
        <mimic joint="gripper_controller" multiplier="1.0" offset="0" />
    </joint>
    <joint name="gripper_left3_to_gripper_left1" type="revolute">
        <axis xyz="0 0 1" />
        <limit effort="1000.0" lower="-0.5" upper="0.5" velocity="1" />
        <parent link="gripper_left3" />
        <child link="gripper_left1" />
        <origin xyz="-0.027 0.016 0" rpy="0 0 0" />
        <mimic joint="gripper_controller" multiplier="-1.0" offset="0" />
    </joint>
    <joint name="gripper_base_to_gripper_right3" type="revolute">
        <axis xyz="0 0 1" />
        <limit effort="1000.0" lower="-0.15" upper="0.7" velocity="1" />
        <parent link="gripper_base" />
        <child link="gripper_right3" />
        <origin xyz="0.012 0.005 0" rpy="0 0 0" />
        <mimic joint="gripper_controller" multiplier="-1.0" offset="0" />
    </joint>
    <joint name="gripper_base_to_gripper_right2" type="revolute">
        <axis xyz="0 0 1" />
        <limit effort="1000.0" lower="-0.5" upper="0.8" velocity="1" />
        <parent link="gripper_base" />
        <child link="gripper_right2" />
        <origin xyz="0.005 0.027 0" rpy="0 0 0" />
        <mimic joint="gripper_controller" multiplier="-1.0" offset="0" />
    </joint>
    <joint name="gripper_right3_to_gripper_right1" type="revolute">
        <axis xyz="0 0 1" />
        <limit effort="1000.0" lower="-0.5" upper="0.5" velocity="1" />
        <parent link="gripper_right3" />
        <child link="gripper_right1" />
        <origin xyz="0.027 0.016 0" rpy="0 0 0" />
        <mimic joint="gripper_controller" multiplier="1.0" offset="0" />
    </joint>
    <transmission name="trans_joint1_to_base">
        <type>transmission_interface/SimpleTransmission</type>
        <joint name="joint1_to_base">
            <hardwareInterface>hardware_interface/PositionJointInterface</hardwareInterface>
        </joint>
        <actuator name="joint1_to_base_motor">
            <hardwareInterface>hardware_interface/PositionJointInterface</hardwareInterface>
            <mechanicalReduction>1</mechanicalReduction>
        </actuator>
    </transmission>
    <transmission name="trans_joint2_to_joint1">
        <type>transmission_interface/SimpleTransmission</type>
        <joint name="joint2_to_joint1">
            <hardwareInterface>hardware_interface/PositionJointInterface</hardwareInterface>
        </joint>
        <actuator name="joint2_to_joint1_motor">
            <hardwareInterface>hardware_interface/PositionJointInterface</hardwareInterface>
            <mechanicalReduction>1</mechanicalReduction>
        </actuator>
    </transmission>
    <transmission name="trans_joint3_to_joint2">
        <type>transmission_interface/SimpleTransmission</type>
        <joint name="joint3_to_joint2">
            <hardwareInterface>hardware_interface/PositionJointInterface</hardwareInterface>
        </joint>
        <actuator name="joint3_to_joint2_motor">
            <hardwareInterface>hardware_interface/PositionJointInterface</hardwareInterface>
            <mechanicalReduction>1</mechanicalReduction>
        </actuator>
    </transmission>
    <transmission name="trans_joint4_to_joint3">
        <type>transmission_interface/SimpleTransmission</type>
        <joint name="joint4_to_joint3">
            <hardwareInterface>hardware_interface/PositionJointInterface</hardwareInterface>
        </joint>
        <actuator name="joint4_to_joint3_motor">
            <hardwareInterface>hardware_interface/PositionJointInterface</hardwareInterface>
            <mechanicalReduction>1</mechanicalReduction>
        </actuator>
    </transmission>
    <transmission name="trans_joint5_to_joint4">
        <type>transmission_interface/SimpleTransmission</type>
        <joint name="joint5_to_joint4">
            <hardwareInterface>hardware_interface/PositionJointInterface</hardwareInterface>
        </joint>
        <actuator name="joint5_to_joint4_motor">
            <hardwareInterface>hardware_interface/PositionJointInterface</hardwareInterface>
            <mechanicalReduction>1</mechanicalReduction>
        </actuator>
    </transmission>
    <transmission name="trans_gripper_controller">
        <type>transmission_interface/SimpleTransmission</type>
        <joint name="gripper_controller">
            <hardwareInterface>hardware_interface/PositionJointInterface</hardwareInterface>
        </joint>
        <actuator name="gripper_controller_motor">
            <hardwareInterface>hardware_interface/PositionJointInterface</hardwareInterface>
            <mechanicalReduction>1</mechanicalReduction>
        </actuator>
    </transmission>
    <gazebo>
         <plugin filename="libroboticsgroup_upatras_gazebo_mimic_joint_plugin.so" name="mimic_gripper_base_to_gripper_left2">
            <joint>gripper_controller</joint>
            <mimicJoint>gripper_base_to_gripper_left2</mimicJoint>
            <multiplier>1.0</multiplier>
            <offset>0.0</offset>
        </plugin>
        <plugin filename="libroboticsgroup_upatras_gazebo_mimic_joint_plugin.so" name="mimic_gripper_left3_to_gripper_left1">
            <joint>gripper_controller</joint>
            <mimicJoint>gripper_left3_to_gripper_left1</mimicJoint>
            <multiplier>-1.0</multiplier>
            <offset>0.0</offset>
        </plugin>
        <plugin filename="libroboticsgroup_upatras_gazebo_mimic_joint_plugin.so" name="mimic_gripper_base_to_gripper_right3">
            <joint>gripper_controller</joint>
            <mimicJoint>gripper_base_to_gripper_right3</mimicJoint>
            <multiplier>-1.0</multiplier>
            <offset>0.0</offset>
        </plugin>
        <plugin filename="libroboticsgroup_upatras_gazebo_mimic_joint_plugin.so" name="mimic_gripper_base_to_gripper_right2">
            <joint>gripper_controller</joint>
            <mimicJoint>gripper_base_to_gripper_right2</mimicJoint>
            <multiplier>-1.0</multiplier>
            <offset>0.0</offset>
        </plugin>
        <plugin filename="libroboticsgroup_upatras_gazebo_mimic_joint_plugin.so" name="mimic_gripper_right3_to_gripper_right1">
            <joint>gripper_controller</joint>
            <mimicJoint>gripper_right3_to_gripper_right1</mimicJoint>
            <multiplier>1.0</multiplier>
            <offset>0.0</offset>
        </plugin>
      <plugin name="gazebo_ros_control" filename="libgazebo_ros_control.so">
            <robotNamespace>/</robotNamespace>
        </plugin>
    </gazebo>
    <gazebo reference="base">
        <selfCollide>true</selfCollide>
    </gazebo>
    <gazebo reference="joint1">
        <selfCollide>true</selfCollide>
    </gazebo>
    <gazebo reference="joint2">
        <selfCollide>true</selfCollide>
    </gazebo>
    <gazebo reference="joint3">
        <selfCollide>true</selfCollide>
    </gazebo>
    <gazebo reference="joint5">
        <selfCollide>true</selfCollide>
    </gazebo>
</robot>
